Workbook

Sheet Resumen
C1: Tech | D1: Pharma | E1: Oil & Gas
B2: Porcentajes del balance general | C2: A | D2: B | E2: C | F2: D | H2: Balance Sheet | I2: O&G | J2: Biotech | K2: Tech | L2: Pharma
B3: Efectivo | C3: 5.13 | D3: 6.46 | E3: 2.34 | F3: 10.22 | H3: Cash & Cash Equivalents | I3: ='O&G>>'!C6 -> 0.044334162 | J3: ='Biotech>>'!C6 -> 0.26583922 | K3: ='Technology>>'!C6 -> 0.088860134 | L3: ='Pharma>>'!C6 -> 0.068277686
B4: Inversiones temporales | C4: 25.12 | D4: 0 | E4: 0 | F4: 2.74 | H4: Short-Term Investments - Total | I4: ='O&G>>'!C7 -> 0.00099538573 | J4: ='Biotech>>'!C7 -> 0.028661459 | K4: ='Technology>>'!C7 -> 0.10693765 | L4: ='Pharma>>'!C7 -> 0.038361788
B5: Cuentas por cobrar | C5: 18.6 | D5: 15.79 | E5: 3.06 | F5: 4.56 | H5: Trade Accounts & Trade Notes Receivable - Net | I5: ='O&G>>'!C8 -> 0.058588596 | J5: ='Biotech>>'!C8 -> 0.12034977 | K5: ='Technology>>'!C8 -> 0.08827602 | L5: ='Pharma>>'!C8 -> 0.11083459
B6: Inventarios | C6: 10.35 | D6: 12.22 | E6: 2.17 | F6: 7.36 | H6: Inventories - Total | I6: ='O&G>>'!C9 -> 0.05870483 | J6: ='Biotech>>'!C9 -> 0.032203793 | K6: ='Technology>>'!C9 -> 0.064861903 | L6: ='Pharma>>'!C9 -> 0.079086347
B7: Otros activos corrientes | C7: 1.54 | D7: 14.99 | E7: 2.92 | F7: 5.6 | H7: Other Current Assets | I7: ='O&G>>'!C10 -> 0.045459006 | J7: ='Biotech>>'!C10 -> 0.047883613 | K7: ='Technology>>'!C10 -> 0.039079975 | L7: ='Pharma>>'!C10 -> 0.072524795
B8: Total Activo Corriente/Total Activos | C8: =SUM(C3:C7) -> 60.74 | D8: =SUM(D3:D7) -> 49.46 | E8: =SUM(E3:E7) -> 10.49 | F8: =SUM(F3:F7) -> 30.48 | H8: Total Current Assets | I8: ='O&G>>'!C11 -> 0.20808198 | J8: ='Biotech>>'!C11 -> 0.49493785 | K8: ='Technology>>'!C11 -> 0.38801568 | L8: ='Pharma>>'!C11 -> 0.36908521
B10: PPE neto/Total Activos | C10: =C11-C12 -> 6.4 | D10: =D11-D12 -> 21.93 | E10: =E11-E12 -> 76.68 | F10: =F11-F12 -> 11.28
B11: PPE/Total Activos | C11: 9.59 | D11: 33.1 | E11: 164.71 | F11: 21.24 | H11: Investments - Long-Term | I11: ='O&G>>'!C13 -> 0.0033376611 | J11: ='Biotech>>'!C13 -> 0.004142382 | K11: ='Technology>>'!C13 -> 0.022570739 | L11: ='Pharma>>'!C13 -> 0.0088218137
B12: Depreciación Acumulada/Total Activos | C12: 3.19 | D12: 11.17 | E12: 88.03 | F12: 9.96 | H12: Property, Plant & Equipment - Net - Total | I12: ='O&G>>'!C14 -> 0.66171933 | J12: ='Biotech>>'!C14 -> 0.070967518 | K12: ='Technology>>'!C14 -> 0.29175239 | L12: ='Pharma>>'!C14 -> 0.19428293
B13: Inversiones a largo plazo/Total Activos | C13: 0 | D13: 2.49 | E13: 0 | F13: 4.02 | H13: Intangible Assets - Total - Net | I13: ='O&G>>'!C15 -> 0.0051757645 | J13: ='Biotech>>'!C15 -> 0.37396698 | K13: ='Technology>>'!C15 -> 0.239886 | L13: ='Pharma>>'!C15 -> 0.3067805
B14: Otros Activos a largo Plazo | C14: 32.86 | D14: 26.11 | E14: 12.84 | F14: 54.22 | H14: Other Non-Current Assets | I14: ='O&G>>'!C16 -> 0.12168527 | J14: ='Biotech>>'!C16 -> 0.055985269 | K14: ='Technology>>'!C16 -> 0.057775191 | L14: ='Pharma>>'!C16 -> 0.12102954
B15: Total Activo No Corriente/Total Activos | C15: =SUM(C13:C14,C10) -> 39.26 | D15: =SUM(D13:D14,D10) -> 50.53 | E15: =SUM(E13:E14,E10) -> 89.52 | F15: =SUM(F13:F14,F10) -> 69.52 | H15: Total Non-Current Assets | I15: ='O&G>>'!C17 -> 0.79191802 | J15: ='Biotech>>'!C17 -> 0.50506215 | K15: ='Technology>>'!C17 -> 0.61198432 | L15: ='Pharma>>'!C17 -> 0.63091479
B17: Total Activos/Total Activos | C17: =C15+C8 -> 100 | D17: =D15+D8 -> 99.99 | E17: =E15+E8 -> 100.01 | F17: =F15+F8 -> 100 | H17: Total Assets | I17: ='O&G>>'!C18 -> 1 | J17: ='Biotech>>'!C18 -> 1 | K17: ='Technology>>'!C18 -> 1 | L17: ='Pharma>>'!C18 -> 1
B19: Cuentas por pagar/Total Activo | C19: 4.74 | D19: 4.78 | E19: 3.9 | F19: 1.47 | H19: Trade Accounts & Trade Notes Payable - Short-Term | I19: ='O&G>>'!C20 -> 0.09140852 | J19: ='Biotech>>'!C20 -> 0.040048569 | K19: ='Technology>>'!C20 -> 0.038486151 | L19: ='Pharma>>'!C20 -> 0.04556699
B20: Obligaciones financieras CP/Total Activo | C20: 0.66 | D20: 1.65 | E20: 2.34 | F20: 0.27 | H20: Short-Term Debt & Current Portion of Long-Term Debt | I20: ='O&G>>'!C21 -> 0.012116478 | J20: ='Biotech>>'!C21 -> 0.027344937 | K20: ='Technology>>'!C21 -> 0.0093649772 | L20: ='Pharma>>'!C21 -> 0.030237708
B21: Otros pasivos corto plazo/Total Activo | C21: 10.14 | D21: 24.89 | E21: 4.96 | F21: 9.64 | H21: Other Current Liabilities | I21: ='O&G>>'!C22 -> 0.047882544 | J21: ='Biotech>>'!C22 -> 0.14517893 | K21: ='Technology>>'!C22 -> 0.09154847 | L21: ='Pharma>>'!C22 -> 0.19167829
B22: Pasivo corriente/Total Activo | C22: =SUM(C19:C21) -> 15.54 | D22: =SUM(D19:D21) -> 31.32 | E22: =SUM(E19:E21) -> 11.2 | F22: =SUM(F19:F21) -> 11.38 | H22: Total Current Liabilities | I22: ='O&G>>'!C23 -> 0.15140754 | J22: ='Biotech>>'!C23 -> 0.21257243 | K22: ='Technology>>'!C23 -> 0.1393996 | L22: ='Pharma>>'!C23 -> 0.26748299
B24: Obligaciones financieras LP/Total Activo | C24: 4.86 | D24: 37.35 | E24: 24.5 | F24: 22.34 | H24: Debt - Long-Term - Total | I24: ='O&G>>'!C25 -> 0.13748423 | J24: ='Biotech>>'!C25 -> 0.21819869 | K24: ='Technology>>'!C25 -> 0.20402456 | L24: ='Pharma>>'!C25 -> 0.29690847
B25: Otros pasivos LP/Total Activo | C25: 3.53 | D25: 7.74 | E25: 20.83 | F25: 4.27 | H25: Other Non-Current Liabilities | I25: ='O&G>>'!C26 -> 0.16745564 | J25: ='Biotech>>'!C26 -> 0.027724485 | K25: ='Technology>>'!C26 -> 0.047132057 | L25: ='Pharma>>'!C26 -> 0.084063527
B26: Pasivo No corriente/Total Activo | C26: =SUM(C24:C25) -> 8.39 | D26: =SUM(D24:D25) -> 45.09 | E26: =SUM(E24:E25) -> 45.33 | F26: =SUM(F24:F25) -> 26.61 | H26: Total Non-Current Liabilities | I26: ='O&G>>'!C27 -> 0.30493988 | J26: ='Biotech>>'!C27 -> 0.24592318 | K26: ='Technology>>'!C27 -> 0.25115662 | L26: ='Pharma>>'!C27 -> 0.380972
B28: Total pasivo/Total Activo | C28: =SUM(C26+C22) -> 23.93 | D28: =SUM(D26+D22) -> 76.41 | E28: =SUM(E26+E22) -> 56.53 | F28: =SUM(F26+F22) -> 37.99 | H28: Total Liabilities | I28: ='O&G>>'!C28 -> 0.45634742 | J28: ='Biotech>>'!C28 -> 0.45849561 | K28: ='Technology>>'!C28 -> 0.39055622 | L28: ='Pharma>>'!C28 -> 0.64845499
B30: Acciones Preferenciales/Total Activo | C30: 0 | D30: 0 | E30: 10.59 | F30: 0
B31: Interes Minoritario/Total Activo | C31: 0 | D31: 0 | E31: 0.67 | F31: 0 | H31: Common Equity - Total | I31: ='O&G>>'!C30 -> 0.52278681 | J31: ='Biotech>>'!C30 -> 0.54044421 | K31: ='Technology>>'!C30 -> 0.59516121 | L31: ='Pharma>>'!C30 -> 0.34131888
B32: Capital suscrito/Total Activo | C32: 76.06 | D32: 23.59 | E32: 32.21 | F32: 62.01 | H32: Other Shareholders' Equity | I32: ='O&G>>'!C31 -> 0.020865768 | J32: ='Biotech>>'!C31 -> 0.0010603126 | K32: ='Technology>>'!C31 -> 0.014282572 | L32: ='Pharma>>'!C31 -> 0.010226119
B33: Total patrimonio/Total Activo | C33: =SUM(C30:C32) -> 76.06 | D33: =SUM(D30:D32) -> 23.59 | E33: =SUM(E30:E32) -> 43.47 | F33: =SUM(F30:F32) -> 62.01 | H33: Total Shareholders' Equity | I33: ='O&G>>'!C32 -> 0.54365258 | J33: ='Biotech>>'!C32 -> 0.54150452 | K33: ='Technology>>'!C32 -> 0.60944378 | L33: ='Pharma>>'!C32 -> 0.35154499
B35: Total Pasivo y Patrimonio/Total Activos | C35: =C33+C28 -> 99.99 | D35: =D33+D28 -> 100 | E35: =E33+E28 -> 100 | F35: =F33+F28 -> 100 | H35: Total Liabilities & Equity | I35: ='O&G>>'!C33 -> 1 | J35: ='Biotech>>'!C33 -> 1.0000001 | K35: ='Technology>>'!C33 -> 1 | L35: ='Pharma>>'!C33 -> 0.99999998
B38: Indicadores Seleccionados | C38: A | D38: B | E38: C | F38: D | H38: Financial Statement
B39: ROE | C39: 1.0149 | D39: 1.0116 | E39: 0.0616 | F39: 0.0739 | H39: Revenue from Business Activities - Total | I39: ='O&G>>'!C37 -> 1 | J39: ='Biotech>>'!C37 -> 1 | K39: ='Technology>>'!C37 -> 1 | L39: ='Pharma>>'!C37 -> 1
B40: Margen operacional | C40: 0.6038 | D40: 0.4035 | E40: 0.1812 | F40: 0.1883 | H40: Cost of Sales | I40: ='O&G>>'!C38 -> 0.79133438 | J40: ='Biotech>>'!C38 -> 0.43841282 | K40: ='Technology>>'!C38 -> 0.46436961 | L40: ='Pharma>>'!C38 -> 0.24492516
B41: Prueba Acida | C41: 3.14 | D41: 0.71 | E41: 0.48 | F41: 1.54 | H41: Gross Profit - Industrials/Property - Total | I41: ='O&G>>'!C39 -> 0.20866562 | J41: ='Biotech>>'!C39 -> 0.56158718 | K41: ='Technology>>'!C39 -> 0.53563039 | L41: ='Pharma>>'!C39 -> 0.75507484
B42: Razon corriente | C42: 3.91 | D42: 1.58 | E42: 0.94 | F42: 2.68 | H42: Selling, General & Administrative Expenses excluding Research & Development Expenses | I42: ='O&G>>'!C40 -> 0.058566314 | J42: ='Biotech>>'!C40 -> 0.2347643 | K42: ='Technology>>'!C40 -> 0.053097745 | L42: ='Pharma>>'!C40 -> 0.20364667
B43: Días de inventario | C43: 91.72 | D43: 352.27 | E43: 0 | F43: 0 | H43: Research & Development Expense - Supplemental | I43: ='O&G>>'!C41 -> 0.0018574354 | J43: ='Biotech>>'!C41 -> 0.18178826 | K43: ='Technology>>'!C41 -> 0.15824983 | L43: ='Pharma>>'!C41 -> 0.19678567
B44: Días de cuentas por cobrar | C44: 51.86 | D44: 79.57 | E44: 45.76 | F44: 0 | H44: — | I44: ='O&G>>'!C42 -> 0.033082048 | J44: ='Biotech>>'!C42 -> -0.0051284893 | K44: ='Technology>>'!C42 -> 2.6753705e-05 | L44: ='Pharma>>'!C42 -> -0.013057139
B45: Rotación de activos totales | C45: 1.36 | D45: 0.68 | E45: 0.25 | F45: 0.34 | H45: Operating Expenses - Total | I45: ='O&G>>'!C43 -> 0.88484018 | J45: ='Biotech>>'!C43 -> 0.84983689 | K45: ='Technology>>'!C43 -> 0.67574394 | L45: ='Pharma>>'!C43 -> 0.63230036
B46: Rotación de activos fijos netos | C46: 20.25 | D46: 3.12 | E46: 0.33 | F46: 2.88 | H46: Earnings before Interest & Taxes (EBIT) | I46: ='O&G>>'!C44 -> 0.11515982 | J46: ='Biotech>>'!C44 -> 0.15016311 | K46: ='Technology>>'!C44 -> 0.32425606 | L46: ='Pharma>>'!C44 -> 0.36769964
H47: Depreciation, Depletion & Amortization - Total | I47: ='O&G>>'!C45 -> 0.1023705 | J47: ='Biotech>>'!C45 -> 0.037461328 | K47: ='Technology>>'!C45 -> 0.14946432 | L47: ='Pharma>>'!C45 -> 0.063811195
H48: Earnings before Interest, Taxes, Depreciation & Amortization (EBITDA) | I48: ='O&G>>'!C46 -> 0.21753032 | J48: ='Biotech>>'!C46 -> 0.18762444 | K48: ='Technology>>'!C46 -> 0.47372039 | L48: ='Pharma>>'!C46 -> 0.43151083
H49: Interest Expense - Net of (Interest Income) | I49: ='O&G>>'!C47 -> 0.0052725984 | J49: ='Biotech>>'!C47 -> 0.0061025372 | K49: ='Technology>>'!C47 -> 0.0085252794 | L49: ='Pharma>>'!C47 -> 0.011073026
...

Sheet O&G>>
C2: Average | D2: =L2 -> Conoco | E2: =M2 -> Chevron | F2: =N2 -> Exxon | G2: =O2 -> Valero | L2: Conoco | M2: Chevron | N2: Exxon | O2: Valero | R2: ICON | S2: ICON | T2: ICON
B4: Balance Sheet | C4: % | D4: % | E4: % | F4: % | G4: % | K4: Balance Sheet | L4: 2025 | M4: 2025 | N4: 2025 | O4: 2025 | Q4: Balance Sheet | R4: 2024 | S4: 2024 | T4: 2024
B6: Cash & Cash Equivalents | C6: =IFERROR(AVERAGE(D6:G6),0) -> 0.044334162 | D6: =IFERROR(L6/L$18,0) -> 0.053280739 | E6: =IFERROR(M6/M$18,0) -> 0.01942212 | F6: =IFERROR(N6/N$18,0) -> 0.023789478 | G6: =IFERROR(O6/O$18,0) -> 0.080844313 | K6: Cash & Cash Equivalents | L6: =SUMIF(INDIRECT("'"&L$2&"'!$A$1:$A$500"),$K6,INDIRECT("'"&L$2&"'!$C$1:$C$500")) -> 6497 | M6: =SUMIF(INDIRECT("'"&M$2&"'!$A$1:$A$500"),$K6,INDIRECT("'"&M$2&"'!$C$1:$C$500")) -> 6293 | N6: =SUMIF(INDIRECT("'"&N$2&"'!$A$1:$A$500"),$K6,INDIRECT("'"&N$2&"'!$C$1:$C$500")) -> 10681 | O6: =SUMIF(INDIRECT("'"&O$2&"'!$A$1:$A$500"),$K6,INDIRECT("'"&O$2&"'!$C$1:$C$500")) -> 4688 | Q6: Cash & Cash Equivalents | R6: =SUMIF(INDIRECT("'"&R$2&"'!$A$1:$A$400"),$K6,INDIRECT("'"&R$2&"'!$b$1:$b$400")) -> 538.79 | S6: =SUMIF(INDIRECT("'"&S$2&"'!$A$1:$A$400"),$K6,INDIRECT("'"&S$2&"'!$b$1:$b$400")) -> 538.79 | T6: =SUMIF(INDIRECT("'"&T$2&"'!$A$1:$A$400"),$K6,INDIRECT("'"&T$2&"'!$b$1:$b$400")) -> 538.79
B7: Short-Term Investments - Total | C7: =IFERROR(AVERAGE(D7:G7),0) -> 0.00099538573 | D7: =IFERROR(L7/L$18,0) -> 0.0039691977 | E7: =IFERROR(M7/M$18,0) -> 1.2345222e-05 | F7: =IFERROR(N7/N$18,0) -> 0 | G7: =IFERROR(O7/O$18,0) -> 0 | K7: Short-Term Investments - Total | L7: =SUMIF(INDIRECT("'"&L$2&"'!$A$1:$A$500"),$K7,INDIRECT("'"&L$2&"'!$C$1:$C$500")) -> 484 | M7: =SUMIF(INDIRECT("'"&M$2&"'!$A$1:$A$500"),$K7,INDIRECT("'"&M$2&"'!$C$1:$C$500")) -> 4 | N7: =SUMIF(INDIRECT("'"&N$2&"'!$A$1:$A$500"),$K7,INDIRECT("'"&N$2&"'!$C$1:$C$500")) -> 0 | O7: =SUMIF(INDIRECT("'"&O$2&"'!$A$1:$A$500"),$K7,INDIRECT("'"&O$2&"'!$C$1:$C$500")) -> 0 | Q7: Short-Term Investments - Total | R7: =SUMIF(INDIRECT("'"&R$2&"'!$A$1:$A$400"),$K7,INDIRECT("'"&R$2&"'!$b$1:$b$400")) -> 0 | S7: =SUMIF(INDIRECT("'"&S$2&"'!$A$1:$A$400"),$K7,INDIRECT("'"&S$2&"'!$b$1:$b$400")) -> 0 | T7: =SUMIF(INDIRECT("'"&T$2&"'!$A$1:$A$400"),$K7,INDIRECT("'"&T$2&"'!$b$1:$b$400")) -> 0
B8: Trade Accounts & Trade Notes Receivable - Net | C8: =IFERROR(AVERAGE(D8:G8),0) -> 0.058588596 | D8: =IFERROR(L8/L$18,0) -> 0.047671377 | E8: =IFERROR(M8/M$18,0) -> 0.055784971 | F8: =IFERROR(N8/N$18,0) -> 0.079611564 | G8: =IFERROR(O8/O$18,0) -> 0.051286473 | K8: Trade Accounts & Trade Notes Receivable - Net | L8: =SUMIF(INDIRECT("'"&L$2&"'!$A$1:$A$500"),$K8,INDIRECT("'"&L$2&"'!$C$1:$C$500")) -> 5813 | M8: =SUMIF(INDIRECT("'"&M$2&"'!$A$1:$A$500"),$K8,INDIRECT("'"&M$2&"'!$C$1:$C$500")) -> 18075 | N8: =SUMIF(INDIRECT("'"&N$2&"'!$A$1:$A$500"),$K8,INDIRECT("'"&N$2&"'!$C$1:$C$500")) -> 35744 | O8: =SUMIF(INDIRECT("'"&O$2&"'!$A$1:$A$500"),$K8,INDIRECT("'"&O$2&"'!$C$1:$C$500")) -> 2974 | Q8: Trade Accounts & Trade Notes Receivable - Net | R8: =SUMIF(INDIRECT("'"&R$2&"'!$A$1:$A$400"),$K8,INDIRECT("'"&R$2&"'!$b$1:$b$400")) -> 1392.76 | S8: =SUMIF(INDIRECT("'"&S$2&"'!$A$1:$A$400"),$K8,INDIRECT("'"&S$2&"'!$b$1:$b$400")) -> 1392.76 | T8: =SUMIF(INDIRECT("'"&T$2&"'!$A$1:$A$400"),$K8,INDIRECT("'"&T$2&"'!$b$1:$b$400")) -> 1392.76
B9: Inventories - Total | C9: =IFERROR(AVERAGE(D9:G9),0) -> 0.05870483 | D9: =IFERROR(L9/L$18,0) -> 0.015360139 | E9: =IFERROR(M9/M$18,0) -> 0.029971112 | F9: =IFERROR(N9/N$18,0) -> 0.058581674 | G9: =IFERROR(O9/O$18,0) -> 0.13090639 | K9: Inventories - Total | L9: =SUMIF(INDIRECT("'"&L$2&"'!$A$1:$A$500"),$K9,INDIRECT("'"&L$2&"'!$C$1:$C$500")) -> 1873 | M9: =SUMIF(INDIRECT("'"&M$2&"'!$A$1:$A$500"),$K9,INDIRECT("'"&M$2&"'!$C$1:$C$500")) -> 9711 | N9: =SUMIF(INDIRECT("'"&N$2&"'!$A$1:$A$500"),$K9,INDIRECT("'"&N$2&"'!$C$1:$C$500")) -> 26302 | O9: =SUMIF(INDIRECT("'"&O$2&"'!$A$1:$A$500"),$K9,INDIRECT("'"&O$2&"'!$C$1:$C$500")) -> 7591 | Q9: Inventories - Total | R9: =SUMIF(INDIRECT("'"&R$2&"'!$A$1:$A$400"),$K9,INDIRECT("'"&R$2&"'!$b$1:$b$400")) -> 0 | S9: =SUMIF(INDIRECT("'"&S$2&"'!$A$1:$A$400"),$K9,INDIRECT("'"&S$2&"'!$b$1:$b$400")) -> 0 | T9: =SUMIF(INDIRECT("'"&T$2&"'!$A$1:$A$400"),$K9,INDIRECT("'"&T$2&"'!$b$1:$b$400")) -> 0
B10: Other Current Assets | C10: =IFERROR(AVERAGE(D10:G10),0) -> 0.045459006 | D10: =IFERROR(L10/L$18,0) -> 0.0070937108 | E10: =IFERROR(M10/M$18,0) -> 0.013792699 | F10: =IFERROR(N10/N$18,0) -> 0.023731569 | G10: =IFERROR(O10/O$18,0) -> 0.13721805 | K10: Other Current Assets | L10: =SUMIF(INDIRECT("'"&L$2&"'!$A$1:$A$500"),$K11,INDIRECT("'"&L$2&"'!$C$1:$C$500"))-SUM(L6:L9) -> 865 | M10: =SUMIF(INDIRECT("'"&M$2&"'!$A$1:$A$500"),$K11,INDIRECT("'"&M$2&"'!$C$1:$C$500"))-SUM(M6:M9) -> 4469 | N10: =SUMIF(INDIRECT("'"&N$2&"'!$A$1:$A$500"),$K11,INDIRECT("'"&N$2&"'!$C$1:$C$500"))-SUM(N6:N9) -> 10655 | O10: =SUMIF(INDIRECT("'"&O$2&"'!$A$1:$A$500"),$K11,INDIRECT("'"&O$2&"'!$C$1:$C$500"))-SUM(O6:O9) -> 7957 | Q10: Other Current Assets | R10: =R11-R6-R7-R8-R9 -> 1343.62 | S10: =S11-S6-S7-S8-S9 -> 1343.62 | T10: =T11-T6-T7-T8-T9 -> 1343.62
B11: Total Current Assets | C11: =IFERROR(AVERAGE(D11:G11),0) -> 0.20808198 | D11: =IFERROR(L11/L$18,0) -> 0.12737516 | E11: =IFERROR(M11/M$18,0) -> 0.11898325 | F11: =IFERROR(N11/N$18,0) -> 0.18571429 | G11: =IFERROR(O11/O$18,0) -> 0.40025523 | K11: Total Current Assets | L11: =SUM(L6:L10) -> 15532 | M11: =SUM(M6:M10) -> 38552 | N11: =SUM(N6:N10) -> 83382 | O11: =SUM(O6:O10) -> 23210 | Q11: Total Current Assets | R11: =SUMIF(INDIRECT("'"&R$2&"'!$A$1:$A$400"),$K11,INDIRECT("'"&R$2&"'!$b$1:$b$400")) -> 3275.17 | S11: =SUMIF(INDIRECT("'"&S$2&"'!$A$1:$A$400"),$K11,INDIRECT("'"&S$2&"'!$b$1:$b$400")) -> 3275.17 | T11: =SUMIF(INDIRECT("'"&T$2&"'!$A$1:$A$400"),$K11,INDIRECT("'"&T$2&"'!$b$1:$b$400")) -> 3275.17
K12: Check Current Assets | L12: =ROUND(SUMIF(INDIRECT("'"&L$2&"'!$A$1:$A$500"),$K$11,INDIRECT("'"&L$2&"'!$C$1:$C$500"))-L11,2) -> 0 | M12: =ROUND(SUMIF(INDIRECT("'"&M$2&"'!$A$1:$A$500"),$K$11,INDIRECT("'"&M$2&"'!$C$1:$C$500"))-M11,2) -> 0 | N12: =ROUND(SUMIF(INDIRECT("'"&N$2&"'!$A$1:$A$500"),$K$11,INDIRECT("'"&N$2&"'!$C$1:$C$500"))-N11,2) -> 0 | O12: =ROUND(SUMIF(INDIRECT("'"&O$2&"'!$A$1:$A$500"),$K$11,INDIRECT("'"&O$2&"'!$C$1:$C$500"))-O11,2) -> 0
B13: Investments - Long-Term | C13: =IFERROR(AVERAGE(D13:G13),0) -> 0.0033376611 | D13: =IFERROR(L13/L$18,0) -> 0.010185421 | E13: =IFERROR(M13/M$18,0) -> 0.0025616335 | F13: =IFERROR(N13/N$18,0) -> 0.00060359036 | G13: =IFERROR(O13/O$18,0) -> 0 | K13: Investments - Long-Term | L13: =SUMIF(INDIRECT("'"&L$2&"'!$A$1:$A$500"),$K13,INDIRECT("'"&L$2&"'!$C$1:$C$500")) -> 1242 | M13: =SUMIF(INDIRECT("'"&M$2&"'!$A$1:$A$500"),$K13,INDIRECT("'"&M$2&"'!$C$1:$C$500")) -> 830 | N13: =SUMIF(INDIRECT("'"&N$2&"'!$A$1:$A$500"),$K13,INDIRECT("'"&N$2&"'!$C$1:$C$500")) -> 271 | O13: =SUMIF(INDIRECT("'"&O$2&"'!$A$1:$A$500"),$K13,INDIRECT("'"&O$2&"'!$C$1:$C$500")) -> 0 | Q13: Investments - Long-Term | R13: =SUMIF(INDIRECT("'"&R$2&"'!$A$1:$A$400"),$K13,INDIRECT("'"&R$2&"'!$b$1:$b$400")) -> 0 | S13: =SUMIF(INDIRECT("'"&S$2&"'!$A$1:$A$400"),$K13,INDIRECT("'"&S$2&"'!$b$1:$b$400")) -> 0 | T13: =SUMIF(INDIRECT("'"&T$2&"'!$A$1:$A$400"),$K13,INDIRECT("'"&T$2&"'!$b$1:$b$400")) -> 0
B14: Property, Plant & Equipment - Net - Total | C14: =IFERROR(AVERAGE(D14:G14),0) -> 0.66171933 | D14: =IFERROR(L14/L$18,0) -> 0.7724272 | E14: =IFERROR(M14/M$18,0) -> 0.6968353 | F14: =IFERROR(N14/N$18,0) -> 0.68287452 | G14: =IFERROR(O14/O$18,0) -> 0.49474029 | K14: Property, Plant & Equipment - Net - Total | L14: =SUMIF(INDIRECT("'"&L$2&"'!$A$1:$A$500"),$K14,INDIRECT("'"&L$2&"'!$C$1:$C$500")) -> 94189 | M14: =SUMIF(INDIRECT("'"&M$2&"'!$A$1:$A$500"),$K14,INDIRECT("'"&M$2&"'!$C$1:$C$500")) -> 225783 | N14: =SUMIF(INDIRECT("'"&N$2&"'!$A$1:$A$500"),$K14,INDIRECT("'"&N$2&"'!$C$1:$C$500")) -> 306597 | O14: =SUMIF(INDIRECT("'"&O$2&"'!$A$1:$A$500"),$K14,INDIRECT("'"&O$2&"'!$C$1:$C$500")) -> 28689 | Q14: Property, Plant & Equipment - Net - Total | R14: =SUMIF(INDIRECT("'"&R$2&"'!$A$1:$A$400"),$K14,INDIRECT("'"&R$2&"'!$b$1:$b$400")) -> 530.48 | S14: =SUMIF(INDIRECT("'"&S$2&"'!$A$1:$A$400"),$K14,INDIRECT("'"&S$2&"'!$b$1:$b$400")) -> 530.48 | T14: =SUMIF(INDIRECT("'"&T$2&"'!$A$1:$A$400"),$K14,INDIRECT("'"&T$2&"'!$b$1:$b$400")) -> 530.48
B15: Intangible Assets - Total - Net | C15: =IFERROR(AVERAGE(D15:G15),0) -> 0.0051757645 | D15: =IFERROR(L15/L$18,0) -> 0 | E15: =IFERROR(M15/M$18,0) -> 0.014098243 | F15: =IFERROR(N15/N$18,0) -> 0 | G15: =IFERROR(O15/O$18,0) -> 0.0066048148 | K15: Intangible Assets - Total - Net | L15: =SUMIF(INDIRECT("'"&L$2&"'!$A$1:$A$500"),$K15,INDIRECT("'"&L$2&"'!$C$1:$C$500")) -> 0 | M15: =SUMIF(INDIRECT("'"&M$2&"'!$A$1:$A$500"),$K15,INDIRECT("'"&M$2&"'!$C$1:$C$500")) -> 4568 | N15: =SUMIF(INDIRECT("'"&N$2&"'!$A$1:$A$500"),$K15,INDIRECT("'"&N$2&"'!$C$1:$C$500")) -> 0 | O15: =SUMIF(INDIRECT("'"&O$2&"'!$A$1:$A$500"),$K15,INDIRECT("'"&O$2&"'!$C$1:$C$500")) -> 383 | Q15: Intangible Assets - Total - Net | R15: =SUMIF(INDIRECT("'"&R$2&"'!$A$1:$A$400"),$K15,INDIRECT("'"&R$2&"'!$b$1:$b$400")) -> 12611.2 | S15: =SUMIF(INDIRECT("'"&S$2&"'!$A$1:$A$400"),$K15,INDIRECT("'"&S$2&"'!$b$1:$b$400")) -> 12611.2 | T15: =SUMIF(INDIRECT("'"&T$2&"'!$A$1:$A$400"),$K15,INDIRECT("'"&T$2&"'!$b$1:$b$400")) -> 12611.2
B16: Other Non-Current Assets | C16: =IFERROR(AVERAGE(D16:G16),0) -> 0.12168527 | D16: =IFERROR(L16/L$18,0) -> 0.090012219 | E16: =IFERROR(M16/M$18,0) -> 0.16752157 | F16: =IFERROR(N16/N$18,0) -> 0.13080761 | G16: =IFERROR(O16/O$18,0) -> 0.098399669 | K16: Other Non-Current Assets | L16: =SUMIF(INDIRECT("'"&L$2&"'!$A$1:$A$500"),$K17,INDIRECT("'"&L$2&"'!$C$1:$C$500"))-SUM(L12:L15) -> 10976 | M16: =SUMIF(INDIRECT("'"&M$2&"'!$A$1:$A$500"),$K17,INDIRECT("'"&M$2&"'!$C$1:$C$500"))-SUM(M12:M15) -> 54279 | N16: =SUMIF(INDIRECT("'"&N$2&"'!$A$1:$A$500"),$K17,INDIRECT("'"&N$2&"'!$C$1:$C$500"))-SUM(N12:N15) -> 58730 | O16: =SUMIF(INDIRECT("'"&O$2&"'!$A$1:$A$500"),$K17,INDIRECT("'"&O$2&"'!$C$1:$C$500"))-SUM(O12:O15) -> 5706 | Q16: Other Non-Current Assets | R16: =R17-R13-R14-R15 -> 217.97 | S16: =S17-S13-S14-S15 -> 217.97 | T16: =T17-T13-T14-T15 -> 217.97
B17: Total Non-Current Assets | C17: =IFERROR(AVERAGE(D17:G17),0) -> 0.79191802 | D17: =IFERROR(L17/L$18,0) -> 0.87262484 | E17: =IFERROR(M17/M$18,0) -> 0.88101675 | F17: =IFERROR(N17/N$18,0) -> 0.81428571 | G17: =IFERROR(O17/O$18,0) -> 0.59974477 | K17: Total Non-Current Assets | L17: =SUM(L13:L16) -> 106407 | M17: =SUM(M13:M16) -> 285460 | N17: =SUM(N13:N16) -> 365598 | O17: =SUM(O13:O16) -> 34778 | Q17: Total Non-Current Assets | R17: =SUMIF(INDIRECT("'"&R$2&"'!$A$1:$A$400"),$K17,INDIRECT("'"&R$2&"'!$b$1:$b$400")) -> 13359.65 | S17: =SUMIF(INDIRECT("'"&S$2&"'!$A$1:$A$400"),$K17,INDIRECT("'"&S$2&"'!$b$1:$b$400")) -> 13359.65 | T17: =SUMIF(INDIRECT("'"&T$2&"'!$A$1:$A$400"),$K17,INDIRECT("'"&T$2&"'!$b$1:$b$400")) -> 13359.65
B18: Total Assets | C18: =IFERROR(AVERAGE(D18:G18),0) -> 1 | D18: =IFERROR(L18/L$18,0) -> 1 | E18: =IFERROR(M18/M$18,0) -> 1 | F18: =IFERROR(N18/N$18,0) -> 1 | G18: =IFERROR(O18/O$18,0) -> 1 | K18: Total Assets | L18: =L17+L11 -> 121939 | M18: =M17+M11 -> 324012 | N18: =N17+N11 -> 448980 | O18: =O17+O11 -> 57988 | Q18: Total Assets | R18: =SUMIF(INDIRECT("'"&R$2&"'!$A$1:$A$400"),$K18,INDIRECT("'"&R$2&"'!$b$1:$b$400")) -> 16634.82 | S18: =SUMIF(INDIRECT("'"&S$2&"'!$A$1:$A$400"),$K18,INDIRECT("'"&S$2&"'!$b$1:$b$400")) -> 16634.82 | T18: =SUMIF(INDIRECT("'"&T$2&"'!$A$1:$A$400"),$K18,INDIRECT("'"&T$2&"'!$b$1:$b$400")) -> 16634.82
K19: Check Total Assets | L19: =ROUND(SUMIF(INDIRECT("'"&L$2&"'!$A$1:$A$500"),$K$18,INDIRECT("'"&L$2&"'!$C$1:$C$500"))-L18,2) -> 0 | M19: =ROUND(SUMIF(INDIRECT("'"&M$2&"'!$A$1:$A$500"),$K$18,INDIRECT("'"&M$2&"'!$C$1:$C$500"))-M18,2) -> 0 | N19: =ROUND(SUMIF(INDIRECT("'"&N$2&"'!$A$1:$A$500"),$K$18,INDIRECT("'"&N$2&"'!$C$1:$C$500"))-N18,2) -> 0 | O19: =ROUND(SUMIF(INDIRECT("'"&O$2&"'!$A$1:$A$500"),$K$18,INDIRECT("'"&O$2&"'!$C$1:$C$500"))-O18,2) -> 0
B20: Trade Accounts & Trade Notes Payable - Short-Term | C20: =IFERROR(AVERAGE(D20:G20),0) -> 0.09140852 | D20: =IFERROR(L20/L$18,0) -> 0.050992709 | E20: =IFERROR(M20/M$18,0) -> 0.059503969 | F20: =IFERROR(N20/N$18,0) -> 0.080290882 | G20: =IFERROR(O20/O$18,0) -> 0.17484652 | K20: Trade Accounts & Trade Notes Payable - Short-Term | L20: =SUMIF(INDIRECT("'"&L$2&"'!$A$1:$A$500"),$K20,INDIRECT("'"&L$2&"'!$C$1:$C$500")) -> 6218 | M20: =SUMIF(INDIRECT("'"&M$2&"'!$A$1:$A$500"),$K20,INDIRECT("'"&M$2&"'!$C$1:$C$500")) -> 19280 | N20: =SUMIF(INDIRECT("'"&N$2&"'!$A$1:$A$500"),$K20,INDIRECT("'"&N$2&"'!$C$1:$C$500")) -> 36049 | O20: =SUMIF(INDIRECT("'"&O$2&"'!$A$1:$A$500"),$K20,INDIRECT("'"&O$2&"'!$C$1:$C$500")) -> 10139 | Q20: Trade Accounts & Trade Notes Payable - Short-Term | R20: =SUMIF(INDIRECT("'"&R$2&"'!$A$1:$A$400"),$K20,INDIRECT("'"&R$2&"'!$b$1:$b$400")) -> 173.03 | S20: =SUMIF(INDIRECT("'"&S$2&"'!$A$1:$A$400"),$K20,INDIRECT("'"&S$2&"'!$b$1:$b$400")) -> 173.03 | T20: =SUMIF(INDIRECT("'"&T$2&"'!$A$1:$A$400"),$K20,INDIRECT("'"&T$2&"'!$b$1:$b$400")) -> 173.03
B21: Short-Term Debt & Current Portion of Long-Term Debt | C21: =IFERROR(AVERAGE(D21:G21),0) -> 0.012116478 | D21: =IFERROR(L21/L$18,0) -> 0.0083648382 | E21: =IFERROR(M21/M$18,0) -> 0.0030153204 | F21: =IFERROR(N21/N$18,0) -> 0.020720299 | G21: =IFERROR(O21/O$18,0) -> 0.016365455 | K21: Short-Term Debt & Current Portion of Long-Term Debt | L21: =SUMIF(INDIRECT("'"&L$2&"'!$A$1:$A$500"),$K21,INDIRECT("'"&L$2&"'!$C$1:$C$500")) -> 1020 | M21: =SUMIF(INDIRECT("'"&M$2&"'!$A$1:$A$500"),$K21,INDIRECT("'"&M$2&"'!$C$1:$C$500")) -> 977 | N21: =SUMIF(INDIRECT("'"&N$2&"'!$A$1:$A$500"),$K21,INDIRECT("'"&N$2&"'!$C$1:$C$500")) -> 9303 | O21: =SUMIF(INDIRECT("'"&O$2&"'!$A$1:$A$500"),$K21,INDIRECT("'"&O$2&"'!$C$1:$C$500")) -> 949 | Q21: Short-Term Debt & Current Portion of Long-Term Debt | R21: =SUMIF(INDIRECT("'"&R$2&"'!$A$1:$A$400"),$K21,INDIRECT("'"&R$2&"'!$b$1:$b$400")) -> 29.76 | S21: =SUMIF(INDIRECT("'"&S$2&"'!$A$1:$A$400"),$K21,INDIRECT("'"&S$2&"'!$b$1:$b$400")) -> 29.76 | T21: =SUMIF(INDIRECT("'"&T$2&"'!$A$1:$A$400"),$K21,INDIRECT("'"&T$2&"'!$b$1:$b$400")) -> 29.76
B22: Other Current Liabilities | C22: =IFERROR(AVERAGE(D22:G22),0) -> 0.047882544 | D22: =IFERROR(L22/L$18,0) -> 0.03882269 | E22: =IFERROR(M22/M$18,0) -> 0.04052319 | F22: =IFERROR(N22/N$18,0) -> 0.060087309 | G22: =IFERROR(O22/O$18,0) -> 0.052096986 | K22: Other Current Liabilities | L22: =SUMIF(INDIRECT("'"&L$2&"'!$A$1:$A$500"),$K23,INDIRECT("'"&L$2&"'!$C$1:$C$500"))-SUM(L20:L21) -> 4734 | M22: =SUMIF(INDIRECT("'"&M$2&"'!$A$1:$A$500"),$K23,INDIRECT("'"&M$2&"'!$C$1:$C$500"))-SUM(M20:M21) -> 13130 | N22: =SUMIF(INDIRECT("'"&N$2&"'!$A$1:$A$500"),$K23,INDIRECT("'"&N$2&"'!$C$1:$C$500"))-SUM(N20:N21) -> 26978 | O22: =SUMIF(INDIRECT("'"&O$2&"'!$A$1:$A$500"),$K23,INDIRECT("'"&O$2&"'!$C$1:$C$500"))-SUM(O20:O21) -> 3021 | Q22: Other Current Liabilities | R22: =R23-R20-R21 -> 2432.7 | S22: =S23-S20-S21 -> 2432.7 | T22: =T23-T20-T21 -> 2432.7
B23: Total Current Liabilities | C23: =IFERROR(AVERAGE(D23:G23),0) -> 0.15140754 | D23: =IFERROR(L23/L$18,0) -> 0.098180238 | E23: =IFERROR(M23/M$18,0) -> 0.10304248 | F23: =IFERROR(N23/N$18,0) -> 0.16109849 | G23: =IFERROR(O23/O$18,0) -> 0.24330896 | K23: Total Current Liabilities | L23: =SUM(L20:L22) -> 11972 | M23: =SUM(M20:M22) -> 33387 | N23: =SUM(N20:N22) -> 72330 | O23: =SUM(O20:O22) -> 14109 | Q23: Total Current Liabilities | R23: =SUMIF(INDIRECT("'"&R$2&"'!$A$1:$A$400"),$K23,INDIRECT("'"&R$2&"'!$b$1:$b$400")) -> 2635.49 | S23: =SUMIF(INDIRECT("'"&S$2&"'!$A$1:$A$400"),$K23,INDIRECT("'"&S$2&"'!$b$1:$b$400")) -> 2635.49 | T23: =SUMIF(INDIRECT("'"&T$2&"'!$A$1:$A$400"),$K23,INDIRECT("'"&T$2&"'!$b$1:$b$400")) -> 2635.49
K24: Check Current Liabilities | L24: =ROUND(SUMIF(INDIRECT("'"&L$2&"'!$A$1:$A$500"),$K$23,INDIRECT("'"&L$2&"'!$C$1:$C$500"))-L23,2) -> 0 | M24: =ROUND(SUMIF(INDIRECT("'"&M$2&"'!$A$1:$A$500"),$K$23,INDIRECT("'"&M$2&"'!$C$1:$C$500"))-M23,2) -> 0 | N24: =ROUND(SUMIF(INDIRECT("'"&N$2&"'!$A$1:$A$500"),$K$23,INDIRECT("'"&N$2&"'!$C$1:$C$500"))-N23,2) -> 0 | O24: =ROUND(SUMIF(INDIRECT("'"&O$2&"'!$A$1:$A$500"),$K$23,INDIRECT("'"&O$2&"'!$C$1:$C$500"))-O23,2) -> 0
B25: Debt - Long-Term - Total | C25: =IFERROR(AVERAGE(D25:G25),0) -> 0.13748423 | D25: =IFERROR(L25/L$18,0) -> 0.18389523 | E25: =IFERROR(M25/M$18,0) -> 0.12277632 | F25: =IFERROR(N25/N$18,0) -> 0.076506749 | G25: =IFERROR(O25/O$18,0) -> 0.16675864 | K25: Debt - Long-Term - Total | L25: =SUMIF(INDIRECT("'"&L$2&"'!$A$1:$A$500"),$K25,INDIRECT("'"&L$2&"'!$C$1:$C$500")) -> 22424 | M25: =SUMIF(INDIRECT("'"&M$2&"'!$A$1:$A$500"),$K25,INDIRECT("'"&M$2&"'!$C$1:$C$500")) -> 39781 | N25: =SUMIF(INDIRECT("'"&N$2&"'!$A$1:$A$500"),$K25,INDIRECT("'"&N$2&"'!$C$1:$C$500")) -> 34350 | O25: =SUMIF(INDIRECT("'"&O$2&"'!$A$1:$A$500"),$K25,INDIRECT("'"&O$2&"'!$C$1:$C$500")) -> 9670 | Q25: Debt - Long-Term - Total | R25: =SUMIF(INDIRECT("'"&R$2&"'!$A$1:$A$400"),$K25,INDIRECT("'"&R$2&"'!$b$1:$b$400")) -> 3396.4 | S25: =SUMIF(INDIRECT("'"&S$2&"'!$A$1:$A$400"),$K25,INDIRECT("'"&S$2&"'!$b$1:$b$400")) -> 3396.4 | T25: =SUMIF(INDIRECT("'"&T$2&"'!$A$1:$A$400"),$K25,INDIRECT("'"&T$2&"'!$b$1:$b$400")) -> 3396.4
B26: Other Non-Current Liabilities | C26: =IFERROR(AVERAGE(D26:G26),0) -> 0.16745564 | D26: =IFERROR(L26/L$18,0) -> 0.18907815 | E26: =IFERROR(M26/M$18,0) -> 0.18106737 | F26: =IFERROR(N26/N$18,0) -> 0.16854648 | G26: =IFERROR(O26/O$18,0) -> 0.13113058 | K26: Other Non-Current Liabilities | L26: =SUMIF(INDIRECT("'"&L$2&"'!$A$1:$A$500"),$K27,INDIRECT("'"&L$2&"'!$C$1:$C$500"))-L25 -> 23056 | M26: =SUMIF(INDIRECT("'"&M$2&"'!$A$1:$A$500"),$K27,INDIRECT("'"&M$2&"'!$C$1:$C$500"))-M25 -> 58668 | N26: =SUMIF(INDIRECT("'"&N$2&"'!$A$1:$A$500"),$K27,INDIRECT("'"&N$2&"'!$C$1:$C$500"))-N25 -> 75674 | O26: =SUMIF(INDIRECT("'"&O$2&"'!$A$1:$A$500"),$K27,INDIRECT("'"&O$2&"'!$C$1:$C$500"))-O25 -> 7604 | Q26: Other Non-Current Liabilities | R26: =SUMIF(INDIRECT("'"&R$2&"'!$A$1:$A$400"),$K26,INDIRECT("'"&R$2&"'!$b$1:$b$400")) -> 210.26 | S26: =SUMIF(INDIRECT("'"&S$2&"'!$A$1:$A$400"),$K26,INDIRECT("'"&S$2&"'!$b$1:$b$400")) -> 210.26 | T26: =SUMIF(INDIRECT("'"&T$2&"'!$A$1:$A$400"),$K26,INDIRECT("'"&T$2&"'!$b$1:$b$400")) -> 210.26
B27: Total Non-Current Liabilities | C27: =IFERROR(AVERAGE(D27:G27),0) -> 0.30493988 | D27: =IFERROR(L27/L$18,0) -> 0.37297337 | E27: =IFERROR(M27/M$18,0) -> 0.30384368 | F27: =IFERROR(N27/N$18,0) -> 0.24505323 | G27: =IFERROR(O27/O$18,0) -> 0.29788922 | K27: Total Non-Current Liabilities | L27: =SUM(L25:L26) -> 45480 | M27: =SUM(M25:M26) -> 98449 | N27: =SUM(N25:N26) -> 110024 | O27: =SUM(O25:O26) -> 17274 | Q27: Total Non-Current Liabilities | R27: =SUMIF(INDIRECT("'"&R$2&"'!$A$1:$A$400"),$K27,INDIRECT("'"&R$2&"'!$b$1:$b$400")) -> 4557.98 | S27: =SUMIF(INDIRECT("'"&S$2&"'!$A$1:$A$400"),$K27,INDIRECT("'"&S$2&"'!$b$1:$b$400")) -> 4557.98 | T27: =SUMIF(INDIRECT("'"&T$2&"'!$A$1:$A$400"),$K27,INDIRECT("'"&T$2&"'!$b$1:$b$400")) -> 4557.98
B28: Total Liabilities | C28: =IFERROR(AVERAGE(D28:G28),0) -> 0.45634742 | D28: =IFERROR(L28/L$18,0) -> 0.47115361 | E28: =IFERROR(M28/M$18,0) -> 0.40688616 | F28: =IFERROR(N28/N$18,0) -> 0.40615172 | G28: =IFERROR(O28/O$18,0) -> 0.54119818 | K28: Total Liabilities | L28: =SUM(L27,L23) -> 57452 | M28: =SUM(M27,M23) -> 131836 | N28: =SUM(N27,N23) -> 182354 | O28: =SUM(O27,O23) -> 31383 | Q28: Total Liabilities | R28: =SUMIF(INDIRECT("'"&R$2&"'!$A$1:$A$400"),$K28,INDIRECT("'"&R$2&"'!$b$1:$b$400")) -> 7193.47 | S28: =SUMIF(INDIRECT("'"&S$2&"'!$A$1:$A$400"),$K28,INDIRECT("'"&S$2&"'!$b$1:$b$400")) -> 7193.47 | T28: =SUMIF(INDIRECT("'"&T$2&"'!$A$1:$A$400"),$K28,INDIRECT("'"&T$2&"'!$b$1:$b$400")) -> 7193.47
K29: Check Total Liabilities | L29: =ROUND(SUMIF(INDIRECT("'"&L$2&"'!$A$1:$A$500"),$K$28,INDIRECT("'"&L$2&"'!$C$1:$C$500"))-L28,2) -> 0 | M29: =ROUND(SUMIF(INDIRECT("'"&M$2&"'!$A$1:$A$500"),$K$28,INDIRECT("'"&M$2&"'!$C$1:$C$500"))-M28,2) -> 0 | N29: =ROUND(SUMIF(INDIRECT("'"&N$2&"'!$A$1:$A$500"),$K$28,INDIRECT("'"&N$2&"'!$C$1:$C$500"))-N28,2) -> 0 | O29: =ROUND(SUMIF(INDIRECT("'"&O$2&"'!$A$1:$A$500"),$K$28,INDIRECT("'"&O$2&"'!$C$1:$C$500"))-O28,2) -> 0
B30: Common Equity - Total | C30: =IFERROR(AVERAGE(D30:G30),0) -> 0.52278681 | D30: =IFERROR(L30/L$18,0) -> 0.52884639 | E30: =IFERROR(M30/M$18,0) -> 0.57544165 | F30: =IFERROR(N30/N$18,0) -> 0.57772284 | G30: =IFERROR(O30/O$18,0) -> 0.40913637 | K30: Common Equity - Total | L30: =SUMIF(INDIRECT("'"&L$2&"'!$A$1:$A$500"),$K30,INDIRECT("'"&L$2&"'!$C$1:$C$500")) -> 64487 | M30: =SUMIF(INDIRECT("'"&M$2&"'!$A$1:$A$500"),$K30,INDIRECT("'"&M$2&"'!$C$1:$C$500")) -> 186450 | N30: =SUMIF(INDIRECT("'"&N$2&"'!$A$1:$A$500"),$K30,INDIRECT("'"&N$2&"'!$C$1:$C$500")) -> 259386 | O30: =SUMIF(INDIRECT("'"&O$2&"'!$A$1:$A$500"),$K30,INDIRECT("'"&O$2&"'!$C$1:$C$500")) -> 23725 | Q30: Common Equity - Total | R30: =SUMIF(INDIRECT("'"&R$2&"'!$A$1:$A$400"),$K30,INDIRECT("'"&R$2&"'!$b$1:$b$400")) -> 9441.35 | S30: =SUMIF(INDIRECT("'"&S$2&"'!$A$1:$A$400"),$K30,INDIRECT("'"&S$2&"'!$b$1:$b$400")) -> 9441.35 | T30: =SUMIF(INDIRECT("'"&T$2&"'!$A$1:$A$400"),$K30,INDIRECT("'"&T$2&"'!$b$1:$b$400")) -> 9441.35
B31: Other Shareholders' Equity | C31: =IFERROR(AVERAGE(D31:G31),0) -> 0.020865768 | D31: =IFERROR(L31/L$18,0) -> 0 | E31: =IFERROR(M31/M$18,0) -> 0.017672185 | F31: =IFERROR(N31/N$18,0) -> 0.01612544 | G31: =IFERROR(O31/O$18,0) -> 0.049665448 | K31: Other Shareholders' Equity | L31: =SUMIF(INDIRECT("'"&L$2&"'!$A$1:$A$500"),$K32,INDIRECT("'"&L$2&"'!$C$1:$C$500"))-L30 -> 0 | M31: =SUMIF(INDIRECT("'"&M$2&"'!$A$1:$A$500"),$K32,INDIRECT("'"&M$2&"'!$C$1:$C$500"))-M30 -> 5726 | N31: =SUMIF(INDIRECT("'"&N$2&"'!$A$1:$A$500"),$K32,INDIRECT("'"&N$2&"'!$C$1:$C$500"))-N30 -> 7240 | O31: =SUMIF(INDIRECT("'"&O$2&"'!$A$1:$A$500"),$K32,INDIRECT("'"&O$2&"'!$C$1:$C$500"))-O30 -> 2880 | Q31: Other Shareholders' Equity | R31: =SUMIF(INDIRECT("'"&R$2&"'!$A$1:$A$400"),$K31,INDIRECT("'"&R$2&"'!$b$1:$b$400")) -> 0 | S31: =SUMIF(INDIRECT("'"&S$2&"'!$A$1:$A$400"),$K31,INDIRECT("'"&S$2&"'!$b$1:$b$400")) -> 0 | T31: =SUMIF(INDIRECT("'"&T$2&"'!$A$1:$A$400"),$K31,INDIRECT("'"&T$2&"'!$b$1:$b$400")) -> 0
B32: Total Shareholders' Equity - including Minority Interest & Hybrid Debt | C32: =IFERROR(AVERAGE(D32:G32),0) -> 0.54365258 | D32: =IFERROR(L32/L$18,0) -> 0.52884639 | E32: =IFERROR(M32/M$18,0) -> 0.59311384 | F32: =IFERROR(N32/N$18,0) -> 0.59384828 | G32: =IFERROR(O32/O$18,0) -> 0.45880182 | K32: Total Shareholders' Equity - including Minority Interest & Hybrid Debt | L32: =SUM(L30:L31) -> 64487 | M32: =SUM(M30:M31) -> 192176 | N32: =SUM(N30:N31) -> 266626 | O32: =SUM(O30:O31) -> 26605 | Q32: Total Shareholders' Equity - including Minority Interest & Hybrid Debt | R32: =SUMIF(INDIRECT("'"&R$2&"'!$A$1:$A$400"),$K32,INDIRECT("'"&R$2&"'!$b$1:$b$400")) -> 9441.35 | S32: =SUMIF(INDIRECT("'"&S$2&"'!$A$1:$A$400"),$K32,INDIRECT("'"&S$2&"'!$b$1:$b$400")) -> 9441.35 | T32: =SUMIF(INDIRECT("'"&T$2&"'!$A$1:$A$400"),$K32,INDIRECT("'"&T$2&"'!$b$1:$b$400")) -> 9441.35
B33: Total Liabilities & Equity | C33: =IFERROR(AVERAGE(D33:G33),0) -> 1 | D33: =IFERROR(L33/L$18,0) -> 1 | E33: =IFERROR(M33/M$18,0) -> 1 | F33: =IFERROR(N33/N$18,0) -> 1 | G33: =IFERROR(O33/O$18,0) -> 1 | K33: Total Liabilities & Equity | L33: =L32+L28 -> 121939 | M33: =M32+M28 -> 324012 | N33: =N32+N28 -> 448980 | O33: =O32+O28 -> 57988 | Q33: Total Liabilities & Equity | R33: =SUMIF(INDIRECT("'"&R$2&"'!$A$1:$A$400"),$K33,INDIRECT("'"&R$2&"'!$b$1:$b$400")) -> 16634.82 | S33: =SUMIF(INDIRECT("'"&S$2&"'!$A$1:$A$400"),$K33,INDIRECT("'"&S$2&"'!$b$1:$b$400")) -> 16634.82 | T33: =SUMIF(INDIRECT("'"&T$2&"'!$A$1:$A$400"),$K33,INDIRECT("'"&T$2&"'!$b$1:$b$400")) -> 16634.82
B34: Check | K34: Check Balance | L34: =ROUND(L18-L33,2) -> 0 | M34: =ROUND(M18-M33,2) -> 0 | N34: =ROUND(N18-N33,2) -> 0 | O34: =ROUND(O18-O33,2) -> 0 | Q34: Check | R34: =R18-R33 -> 0 | S34: =S18-S33 -> 0 | T34: =T18-T33 -> 0
B36: Financial Statement | K36: Financial Statement | L36: 2025 | M36: 2025 | N36: 2025 | O36: 2025 | Q36: Financial Statement | R36: 2024 | S36: 2024 | T36: 2024
B37: Revenue from Business Activities - Total | C37: =IFERROR(AVERAGE(D37:G37),0) -> 1 | D37: =IFERROR(L37/L$37,0) -> 1 | E37: =IFERROR(M37/M$37,0) -> 1 | F37: =IFERROR(N37/N$37,0) -> 1 | G37: =IFERROR(O37/O$37,0) -> 1 | K37: Revenue from Business Activities - Total | L37: =SUMIF(INDIRECT("'"&L$2&"'!$A$1:$A$500"),$K37,INDIRECT("'"&L$2&"'!$C$1:$C$500")) -> 58944 | M37: =SUMIF(INDIRECT("'"&M$2&"'!$A$1:$A$500"),$K37,INDIRECT("'"&M$2&"'!$C$1:$C$500")) -> 184432 | N37: =SUMIF(INDIRECT("'"&N$2&"'!$A$1:$A$500"),$K37,INDIRECT("'"&N$2&"'!$C$1:$C$500")) -> 323905 | O37: =SUMIF(INDIRECT("'"&O$2&"'!$A$1:$A$500"),$K37,INDIRECT("'"&O$2&"'!$C$1:$C$500")) -> 115967 | Q37: Revenue from Business Activities - Total | R37: =SUMIF(INDIRECT("'"&R$2&"'!$A$1:$A$400"),$K37,INDIRECT("'"&R$2&"'!$b$1:$b$400")) -> 8188.99 | S37: =SUMIF(INDIRECT("'"&S$2&"'!$A$1:$A$400"),$K37,INDIRECT("'"&S$2&"'!$b$1:$b$400")) -> 8188.99 | T37: =SUMIF(INDIRECT("'"&T$2&"'!$A$1:$A$400"),$K37,INDIRECT("'"&T$2&"'!$b$1:$b$400")) -> 8188.99
B38: Cost of Sales | C38: =IFERROR(AVERAGE(D38:G38),0) -> 0.79133438 | D38: =IFERROR(L38/L$37,0) -> 0.74548724 | E38: =IFERROR(M38/M$37,0) -> 0.69181595 | F38: =IFERROR(N38/N$37,0) -> 0.77433198 | G38: =IFERROR(O38/O$37,0) -> 0.95370235 | K38: Cost of Operating Revenue | L38: =SUMIF(INDIRECT("'"&L$2&"'!$A$1:$A$500"),$K38,INDIRECT("'"&L$2&"'!$C$1:$C$500")) -> 43942 | M38: =SUMIF(INDIRECT("'"&M$2&"'!$A$1:$A$500"),$K38,INDIRECT("'"&M$2&"'!$C$1:$C$500")) -> 127593 | N38: =SUMIF(INDIRECT("'"&N$2&"'!$A$1:$A$500"),$K38,INDIRECT("'"&N$2&"'!$C$1:$C$500")) -> 250810 | O38: =SUMIF(INDIRECT("'"&O$2&"'!$A$1:$A$500"),$K38,INDIRECT("'"&O$2&"'!$C$1:$C$500")) -> 110598 | Q38: Cost of Sales | R38: =SUMIF(INDIRECT("'"&R$2&"'!$A$1:$A$400"),$K38,INDIRECT("'"&R$2&"'!$b$1:$b$400")) -> 6306.56 | S38: =SUMIF(INDIRECT("'"&S$2&"'!$A$1:$A$400"),$K38,INDIRECT("'"&S$2&"'!$b$1:$b$400")) -> 6306.56 | T38: =SUMIF(INDIRECT("'"&T$2&"'!$A$1:$A$400"),$K38,INDIRECT("'"&T$2&"'!$b$1:$b$400")) -> 6306.56
B39: Gross Profit - Industrials/Property - Total | C39: =IFERROR(AVERAGE(D39:G39),0) -> 0.20866562 | D39: =IFERROR(L39/L$37,0) -> 0.25451276 | E39: =IFERROR(M39/M$37,0) -> 0.30818405 | F39: =IFERROR(N39/N$37,0) -> 0.22566802 | G39: =IFERROR(O39/O$37,0) -> 0.046297654 | K39: Gross Profit - Industrials/Property - Total | L39: =L37-L38 -> 15002 | M39: =M37-M38 -> 56839 | N39: =N37-N38 -> 73095 | O39: =O37-O38 -> 5369 | Q39: Gross Profit - Industrials/Property - Total | R39: =SUMIF(INDIRECT("'"&R$2&"'!$A$1:$A$400"),$K39,INDIRECT("'"&R$2&"'!$b$1:$b$400")) -> 1882.43 | S39: =SUMIF(INDIRECT("'"&S$2&"'!$A$1:$A$400"),$K39,INDIRECT("'"&S$2&"'!$b$1:$b$400")) -> 1882.43 | T39: =SUMIF(INDIRECT("'"&T$2&"'!$A$1:$A$400"),$K39,INDIRECT("'"&T$2&"'!$b$1:$b$400")) -> 1882.43
B40: Selling, General & Administrative Expenses excluding Research & Development Expenses | C40: =IFERROR(AVERAGE(D40:G40),0) -> 0.058566314 | D40: =IFERROR(L40/L$37,0) -> 0.054373643 | E40: =IFERROR(M40/M$37,0) -> 0.059534137 | F40: =IFERROR(N40/N$37,0) -> 0.11137216 | G40: =IFERROR(O40/O$37,0) -> 0.0089853148 | K40: Selling, General & Administrative Expenses excluding Research & Development Expenses | L40: =SUMIF( INDIRECT("'"&L$2&"'!$A$1:$A$500"), $K40, INDIRECT("'"&L$2&"'!$C$1:$C$500") ) -> 3205 | M40: =SUMIF( INDIRECT("'"&M$2&"'!$A$1:$A$500"), $K40, INDIRECT("'"&M$2&"'!$C$1:$C$500") ) -> 10980 | N40: =SUMIF( INDIRECT("'"&N$2&"'!$A$1:$A$500"), $K40, INDIRECT("'"&N$2&"'!$C$1:$C$500") ) -> 36074 | O40: =SUMIF( INDIRECT("'"&O$2&"'!$A$1:$A$500"), $K40, INDIRECT("'"&O$2&"'!$C$1:$C$500") ) -> 1042 | Q40: Selling, General & Administrative Expenses excluding Research & Development Expenses | R40: =SUMIF(INDIRECT("'"&R$2&"'!$A$1:$A$400"),$K40,INDIRECT("'"&R$2&"'!$b$1:$b$400")) -> 728.35 | S40: =SUMIF(INDIRECT("'"&S$2&"'!$A$1:$A$400"),$K40,INDIRECT("'"&S$2&"'!$b$1:$b$400")) -> 728.35 | T40: =SUMIF(INDIRECT("'"&T$2&"'!$A$1:$A$400"),$K40,INDIRECT("'"&T$2&"'!$b$1:$b$400")) -> 728.35
B41: Research & Development Expense - Supplemental | C41: =IFERROR(AVERAGE(D41:G41),0) -> 0.0018574354 | D41: =IFERROR(L41/L$37,0) -> 0.0013232899 | E41: =IFERROR(M41/M$37,0) -> 0.0023152164 | F41: =IFERROR(N41/N$37,0) -> 0.0037912351 | G41: =IFERROR(O41/O$37,0) -> 0 | K41: Research & Development Expense - Supplemental | L41: =SUMIF( INDIRECT("'"&L$2&"'!$A$1:$A$500"), $K41, INDIRECT("'"&L$2&"'!$C$1:$C$500") ) -> 78 | M41: =SUMIF( INDIRECT("'"&M$2&"'!$A$1:$A$500"), $K41, INDIRECT("'"&M$2&"'!$C$1:$C$500") ) -> 427 | N41: =SUMIF( INDIRECT("'"&N$2&"'!$A$1:$A$500"), $K41, INDIRECT("'"&N$2&"'!$C$1:$C$500") ) -> 1228 | O41: =SUMIF( INDIRECT("'"&O$2&"'!$A$1:$A$500"), $K41, INDIRECT("'"&O$2&"'!$C$1:$C$500") ) -> 0 | Q41: Research & Development Expense - Supplemental | R41: =SUMIF(INDIRECT("'"&R$2&"'!$A$1:$A$400"),$K41,INDIRECT("'"&R$2&"'!$b$1:$b$400")) -> 0 | S41: =SUMIF(INDIRECT("'"&S$2&"'!$A$1:$A$400"),$K41,INDIRECT("'"&S$2&"'!$b$1:$b$400")) -> 0 | T41: =SUMIF(INDIRECT("'"&T$2&"'!$A$1:$A$400"),$K41,INDIRECT("'"&T$2&"'!$b$1:$b$400")) -> 0
B42: — | C42: =IFERROR(AVERAGE(D42:G42),0) -> 0.033082048 | D42: =IFERROR(L42/L$37,0) -> -0.0035118078 | E42: =IFERROR(M42/M$37,0) -> 0.14456819 | F42: =IFERROR(N42/N$37,0) -> -0.0088575354 | G42: =IFERROR(O42/O$37,0) -> 0.00012934714 | K42: Other | L42: =SUMIF(INDIRECT("'"&L$2&"'!$A$1:$A$500"),$K$43,INDIRECT("'"&L$2&"'!$C$1:$C$500"))-L38-L40-L41 -> -207 | M42: =SUMIF(INDIRECT("'"&M$2&"'!$A$1:$A$500"),$K$43,INDIRECT("'"&M$2&"'!$C$1:$C$500"))-M38-M40-M41 -> 26663 | N42: =SUMIF(INDIRECT("'"&N$2&"'!$A$1:$A$500"),$K$43,INDIRECT("'"&N$2&"'!$C$1:$C$500"))-N38-N40-N41 -> -2869 | O42: =SUMIF(INDIRECT("'"&O$2&"'!$A$1:$A$500"),$K$43,INDIRECT("'"&O$2&"'!$C$1:$C$500"))-O38-O40-O41 -> 15 | Q42: Other | R42: =SUMIF(INDIRECT("'"&R$2&"'!$A$1:$A$400"),$K42,INDIRECT("'"&R$2&"'!$b$1:$b$400")) -> 0 | S42: =SUMIF(INDIRECT("'"&S$2&"'!$A$1:$A$400"),$K42,INDIRECT("'"&S$2&"'!$b$1:$b$400")) -> 0 | T42: =SUMIF(INDIRECT("'"&T$2&"'!$A$1:$A$400"),$K42,INDIRECT("'"&T$2&"'!$b$1:$b$400")) -> 0
B43: Operating Expenses - Total | C43: =IFERROR(AVERAGE(D43:G43),0) -> 0.88484018 | D43: =IFERROR(L43/L$37,0) -> 0.79767237 | E43: =IFERROR(M43/M$37,0) -> 0.8982335 | F43: =IFERROR(N43/N$37,0) -> 0.88063784 | G43: =IFERROR(O43/O$37,0) -> 0.96281701 | K43: Operating Expenses - Total | L43: =SUM(L38,L40:L42) -> 47018 | M43: =SUM(M38,M40:M42) -> 165663 | N43: =SUM(N38,N40:N42) -> 285243 | O43: =SUM(O38,O40:O42) -> 111655 | Q43: Operating Expenses - Total | R43: =SUMIF(INDIRECT("'"&R$2&"'!$A$1:$A$400"),$K43,INDIRECT("'"&R$2&"'!$b$1:$b$400")) -> 7034.91 | S43: =SUMIF(INDIRECT("'"&S$2&"'!$A$1:$A$400"),$K43,INDIRECT("'"&S$2&"'!$b$1:$b$400")) -> 7034.91 | T43: =SUMIF(INDIRECT("'"&T$2&"'!$A$1:$A$400"),$K43,INDIRECT("'"&T$2&"'!$b$1:$b$400")) -> 7034.91
B44: Earnings before Interest & Taxes (EBIT) | C44: =IFERROR(AVERAGE(D44:G44),0) -> 0.11515982 | D44: =IFERROR(L44/L$37,0) -> 0.20232763 | E44: =IFERROR(M44/M$37,0) -> 0.1017665 | F44: =IFERROR(N44/N$37,0) -> 0.11936216 | G44: =IFERROR(O44/O$37,0) -> 0.037182992 | K44: Earnings before Interest & Taxes (EBIT) | L44: =L37-L43 -> 11926 | M44: =M37-M43 -> 18769 | N44: =N37-N43 -> 38662 | O44: =O37-O43 -> 4312 | Q44: Earnings before Interest & Taxes (EBIT) | R44: =SUMIF(INDIRECT("'"&R$2&"'!$A$1:$A$400"),$K44,INDIRECT("'"&R$2&"'!$b$1:$b$400")) -> 1154.08 | S44: =SUMIF(INDIRECT("'"&S$2&"'!$A$1:$A$400"),$K44,INDIRECT("'"&S$2&"'!$b$1:$b$400")) -> 1154.08 | T44: =SUMIF(INDIRECT("'"&T$2&"'!$A$1:$A$400"),$K44,INDIRECT("'"&T$2&"'!$b$1:$b$400")) -> 1154.08
...

Sheet Conoco
A1: Company Fundamentals - Balance Sheet
A2: Company Name | B2: ConocoPhillips (COP.N)
A3: Country of Exchange | B3: United States of America
A4: Country of Headquarters | B4: United States of America
A5: TRBC Industry Group | B5: Oil & Gas
A6: CF Template | B6: IND
A7: Consolidation Basis | B7: Consolidated
A8: Scaling | B8: Millions
A9: Period | B9: Annual
A10: Export Date | B10: 46295.614
A11: Statement Data | B11: 2024 | C11: 2025
A12: Period End Date | B12: 45657 | C12: 46022
A13: Standardized Currency | B13: USD | C13: USD
A14: Balance Sheet - Standardized (Currency: US Dollar)
A15: Field Name | B15: 30-12-2024 | C15: 30-12-2025
A16: Current Assets
A17: Cash & Short-Term Investments | B17: 6114 | C17: 6981
A18: Cash & Cash Equivalents | B18: 5607 | C18: 6497
A19: Short-Term Investments - Total | B19: 507 | C19: 484
A20: Loans & Receivables - Net - Short-Term | B20: 6695 | C20: 5813
A21: Trade Accounts & Trade Notes Receivable - Net | B21: 6695 | C21: 5813
A22: Trade Accounts & Trade Notes Receivable - Gross | B22: 6702 | C22: 5817
A23: Provision - Trade Accounts & Trade Notes Receivable | B23: 7 | C23: 4
A24: Inventories - Total | B24: 1809 | C24: 1873
A25: Inventories - Raw Materials | B25: 902 | C25: 873
A26: Inventories - Finished Goods | B26: 907 | C26: 1000
A27: Prepaid Expenses - Short-Term | B27: 1029 | C27: 865
A28: Total Current Assets | B28: 15647 | C28: 15532
A29: Non-Current Assets
A30: Investments - Long-Term | B30: 1145 | C30: 1242
A31: Investments - Available for Sale/Held to Maturity - Long-Term | B31: 1145 | C31: 1242
A32: Investments in Associates, Joint Ventures and Unconsolidated Subsidiaries | B32: 8611 | C32: 8833
A33: Receivables & Loans - Long-Term | B33: 113 | C33: 110
A34: Accounts & Notes Receivable - Trade - Net - Long-Term | B34: 113 | C34: 110
A35: Property, Plant & Equipment - Net - Total | B35: 95373 | C35: 94189
A36: Property, Plant & Equipment - excluding Assets Leased Out - Net - Total | B36: 95373 | C36: 94189
A37: Property, Plant & Equipment - Gross - Total | B37: 176445 | C37: 184585
A38: Property, Plant & Equipment - excluding Assets Leased Out - Gross | B38: 176445 | C38: 184585
A39: Right of Use Tangible Assets - Total - Gross | B39: 1017 | C39: 950
A40: Right of Use Tangible Assets - Operating Lease - Gross | B40: 1017 | C40: 950
...

Sheet Chevron
A1: Company Fundamentals - Balance Sheet
A2: Company Name | B2: Chevron Corporation (CVX.N)
A3: Country of Exchange | B3: United States of America
A4: Country of Headquarters | B4: United States of America
A5: TRBC Industry Group | B5: Oil & Gas
A6: CF Template | B6: IND
A7: Consolidation Basis | B7: Consolidated
A8: Scaling | B8: Millions
A9: Period | B9: Annual
A10: Export Date | B10: 46295.613
A11: Statement Data | B11: 2024 | C11: 2025
A12: Period End Date | B12: 45657 | C12: 46022
A13: Standardized Currency | B13: USD | C13: USD
A14: Balance Sheet - Standardized (Currency: US Dollar)
A15: Field Name | B15: 30-12-2024 | C15: 30-12-2025
A16: Current Assets
A17: Cash & Short-Term Investments | B17: 6785 | C17: 6297
A18: Cash & Cash Equivalents | B18: 6781 | C18: 6293
A19: Short-Term Investments - Total | B19: 4 | C19: 4
A20: Loans & Receivables - Net - Short-Term | B20: 20684 | C20: 18075
A21: Trade Accounts & Trade Notes Receivable - Net | B21: 20684 | C21: 18075
A22: Trade Accounts & Trade Notes Receivable - Gross | B22: 20943 | C22: 18251
A23: Provision - Trade Accounts & Trade Notes Receivable | B23: 259 | C23: 176
A24: Inventories - Total | B24: 9074 | C24: 9711
A25: Inventories - Raw Materials | B25: 2584 | C25: 3071
A26: Inventories - Finished Goods | B26: 6490 | C26: 6640
A27: Prepaid Expenses - Short-Term | B27: 4087 | C27: 4295
A28: Other Current Assets - Total | B28: 281 | C28: 174
... A30: Total Current Assets | B30: 40911 | C30: 38552
A31: Non-Current Assets
A32: Investments - Long-Term | B32: 820 | C32: 830
A33: Investments - Available for Sale/Held to Maturity - Long-Term | B33: 820 | C33: 830
A34: Investments in Associates, Joint Ventures and Unconsolidated Subsidiaries | B34: 46618 | C34: 43037
A35: Receivables & Loans - Long-Term | B35: 877 | C35: 1035
A36: Loans - Long-Term | B36: 877 | C36: 1251
A37: Provision - Doubtful Accounts - Long-Term | C37: 216
A38: Property, Plant & Equipment - Net - Total | B38: 153114 | C38: 225783
A39: Property, Plant & Equipment - excluding Assets Leased Out - Net - Total | B39: 153114 | C39: 225783
A40: Right of Use Tangible Assets - Total - Net | B40: 5315 | C40: 6054
A41: Right of Use Tangible Assets - Operating Lease - Net | B41: 5315 | C41: 6054
...

Sheet Exxon
A1: Company Fundamentals - Balance Sheet
A2: Company Name | B2: Exxonmobil Holdings Corp (XOM.N)
A3: Country of Exchange | B3: United States of America
A4: Country of Headquarters | B4: United States of America
A5: TRBC Industry Group | B5: Oil & Gas
A6: CF Template | B6: IND
A7: Consolidation Basis | B7: Consolidated
A8: Scaling | B8: Millions
A9: Period | B9: Annual
A10: Export Date | B10: 46295.61
A11: Statement Data | B11: 2024 | C11: 2025
A12: Period End Date | B12: 45657 | C12: 46022
A13: Standardized Currency | B13: USD | C13: USD
A14: Balance Sheet - Standardized (Currency: US Dollar)
A15: Field Name | B15: 30-12-2024 | C15: 30-12-2025
A16: Current Assets
A17: Cash & Short-Term Investments | B17: 23029 | C17: 10681
A18: Cash & Cash Equivalents | B18: 23029 | C18: 10681
A19: Loans & Receivables - Net - Short-Term | B19: 43681 | C19: 44562
A20: Trade Accounts & Trade Notes Receivable - Net | B20: 35282 | C20: 35744
A21: Trade Accounts & Trade Notes Receivable - Gross | B21: 35444 | C21: 36014
A22: Provision - Trade Accounts & Trade Notes Receivable | B22: 162 | C22: 270
A23: Loans - Short-Term | B23: 8399 | C23: 8818
A24: Inventories - Total | B24: 23524 | C24: 26302
A25: Inventories - Raw Materials | B25: 4080 | C25: 3323
A26: Inventories - Finished Goods | B26: 19444 | C26: 22979
A27: Other Current Assets - Total | B27: 1756 | C27: 1837
A28: Restricted Accounts - Short-Term | B28: 158 | C28: 0
... A30: Total Current Assets | B30: 91990 | C30: 83382
A31: Non-Current Assets
A32: Investments - Long-Term | B32: 343 | C32: 271
A33: Investments - Available for Sale/Held to Maturity - Long-Term | B33: 343 | C33: 271
A34: Investments in Associates, Joint Ventures and Unconsolidated Subsidiaries | B34: 34010 | C34: 32653
A35: Receivables & Loans - Long-Term | B35: 12847 | C35: 12393
A36: Accounts & Notes Receivable - Trade - Net - Long-Term | B36: 5763 | C36: 6263
A37: Loans - Long-Term | B37: 7084 | C37: 6130
A38: Property, Plant & Equipment - Net - Total | B38: 301441 | C38: 306597
A39: Property, Plant & Equipment - excluding Assets Leased Out - Net - Total | B39: 301441 | C39: 306597
A40: Property, Plant & Equipment - Gross - Total | B40: 561026 | C40: 577283
A41: Property, Plant & Equipment - excluding Assets Leased Out - Gross | B41: 561026 | C41: 577283
...

Sheet Valero
A1: Company Fundamentals - Balance Sheet
A2: Company Name | B2: Valero Energy Corp (VLO.N)
A3: Country of Exchange | B3: United States of America
A4: Country of Headquarters | B4: United States of America
A5: TRBC Industry Group | B5: Oil & Gas
A6: CF Template | B6: IND
A7: Consolidation Basis | B7: Consolidated
A8: Scaling | B8: Millions
A9: Period | B9: Annual
A10: Export Date | B10: 46296.613
A11: Statement Data | B11: 2024 | C11: 2025
A12: Period End Date | B12: 45657 | C12: 46022
A13: Standardized Currency | B13: USD | C13: USD
A14: Balance Sheet - Standardized (Currency: US Dollar)
A15: Field Name | B15: 30-12-2024 | C15: 30-12-2025
A16: Current Assets
A17: Cash & Short-Term Investments | B17: 4657 | C17: 4688
A18: Cash & Cash Equivalents | B18: 4657 | C18: 4688
A19: Loans & Receivables - Net - Short-Term | B19: 10708 | C19: 9877
A20: Trade Accounts & Trade Notes Receivable - Net | B20: 3919 | C20: 2974
A21: Trade Accounts & Trade Notes Receivable - Gross | B21: 3939 | C21: 2993
A22: Provision - Trade Accounts & Trade Notes Receivable | B22: 20 | C22: 19
A23: Income Tax - Receivables - Short-Term | B23: 272 | C23: 236
A24: Receivables - Other - Total | B24: 6517 | C24: 6667
A25: Inventories - Total | B25: 7761 | C25: 7591
A26: Inventories - Raw Materials | B26: 364 | C26: 406
A27: Inventories - Other - Total | B27: 7397 | C27: 7185
A28: Prepaid Expenses - Short-Term | B28: 611 | C28: 1054
A29: Total Current Assets | B29: 23737 | C29: 23210
A30: Non-Current Assets
A31: Investments in Associates, Joint Ventures and Unconsolidated Subsidiaries | B31: 695 | C31: 684
A32: Receivables & Loans - Long-Term | B32: 317 | C32: 347
A33: Receivables - Other - Net - Long-Term | B33: 317 | C33: 347
A34: Property, Plant & Equipment - Net - Total | B34: 30412 | C34: 28689
A35: Property, Plant & Equipment - excluding Assets Leased Out - Net - Total | B35: 30412 | C35: 28689
A36: Property, Plant & Equipment - Gross - Total | B36: 53466 | C36: 51163
A37: Property, Plant & Equipment - excluding Assets Leased Out - Gross | B37: 53466 | C37: 51163
A38: Land & Buildings - Gross | B38: 1647 | C38: 1591
A39: Land/Improvements - Gross | B39: 500 | C39: 509
A40: Buildings - Gross | B40: 1147 | C40: 1082
...

Sheet Biotech>>
C2: Average | D2: =L2 -> IQVIA | E2: =M2 -> Argenx | F2: =N2 -> Beone | G2: =O2 -> ICON | L2: IQVIA | M2: Argenx | N2: Beone | O2: ICON
B4: Balance Sheet | D4: % | E4: % | F4: % | G4: % | K4: Balance Sheet | L4: 2025 | M4: 2025 | N4: 2025 | O4: 2025
B6: Cash & Cash Equivalents | C6: =IFERROR(AVERAGE(D6:G6),0) -> 0.26583922 | D6: =IFERROR(L6/L$18,0) -> 0.06612343 | E6: =IFERROR(M6/M$18,0) -> 0.40209774 | F6: =IFERROR(N6/N$18,0) -> 0.55535093 | G6: =IFERROR(O6/O$18,0) -> 0.039784779 | K6: Cash & Cash Equivalents | L6: =SUMIF(INDIRECT("'"&L$2&"'!$A$1:$A$500"),$K6,INDIRECT("'"&L$2&"'!$C$1:$C$500")) -> 1980 | M6: =SUMIF(INDIRECT("'"&M$2&"'!$A$1:$A$500"),$K6,INDIRECT("'"&M$2&"'!$C$1:$C$500")) -> 3491.29 | N6: =SUMIF(INDIRECT("'"&N$2&"'!$A$1:$A$500"),$K6,INDIRECT("'"&N$2&"'!$C$1:$C$500")) -> 4547.53 | O6: =SUMIF(INDIRECT("'"&O$2&"'!$A$1:$A$500"),$K6,INDIRECT("'"&O$2&"'!$C$1:$C$500")) -> 647.29
B7: Short-Term Investments - Total | C7: =IFERROR(AVERAGE(D7:G7),0) -> 0.028661459 | D7: =IFERROR(L7/L$18,0) -> 0.0053767032 | E7: =IFERROR(M7/M$18,0) -> 0.10926913 | F7: =IFERROR(N7/N$18,0) -> 0 | G7: =IFERROR(O7/O$18,0) -> 0 | K7: Short-Term Investments - Total | L7: =SUMIF(INDIRECT("'"&L$2&"'!$A$1:$A$500"),$K7,INDIRECT("'"&L$2&"'!$C$1:$C$500")) -> 161 | M7: =SUMIF(INDIRECT("'"&M$2&"'!$A$1:$A$500"),$K7,INDIRECT("'"&M$2&"'!$C$1:$C$500")) -> 948.75 | N7: =SUMIF(INDIRECT("'"&N$2&"'!$A$1:$A$500"),$K7,INDIRECT("'"&N$2&"'!$C$1:$C$500")) -> 0 | O7: =SUMIF(INDIRECT("'"&O$2&"'!$A$1:$A$500"),$K7,INDIRECT("'"&O$2&"'!$C$1:$C$500")) -> 0
B8: Trade Accounts & Trade Notes Receivable - Net | C8: =IFERROR(AVERAGE(D8:G8),0) -> 0.12034977 | D8: =IFERROR(L8/L$18,0) -> 0.11354528 | E8: =IFERROR(M8/M$18,0) -> 0.17155628 | F8: =IFERROR(N8/N$18,0) -> 0.10564482 | G8: =IFERROR(O8/O$18,0) -> 0.090652676 | K8: Trade Accounts & Trade Notes Receivable - Net | L8: =SUMIF(INDIRECT("'"&L$2&"'!$A$1:$A$500"),$K8,INDIRECT("'"&L$2&"'!$C$1:$C$500")) -> 3400 | M8: =SUMIF(INDIRECT("'"&M$2&"'!$A$1:$A$500"),$K8,INDIRECT("'"&M$2&"'!$C$1:$C$500")) -> 1489.57 | N8: =SUMIF(INDIRECT("'"&N$2&"'!$A$1:$A$500"),$K8,INDIRECT("'"&N$2&"'!$C$1:$C$500")) -> 865.08 | O8: =SUMIF(INDIRECT("'"&O$2&"'!$A$1:$A$500"),$K8,INDIRECT("'"&O$2&"'!$C$1:$C$500")) -> 1474.9
B9: Inventories - Total | C9: =IFERROR(AVERAGE(D9:G9),0) -> 0.032203793 | D9: =IFERROR(L9/L$18,0) -> 0 | E9: =IFERROR(M9/M$18,0) -> 0.054537246 | F9: =IFERROR(N9/N$18,0) -> 0.074277926 | G9: =IFERROR(O9/O$18,0) -> 0 | K9: Inventories - Total | L9: =SUMIF(INDIRECT("'"&L$2&"'!$A$1:$A$500"),$K9,INDIRECT("'"&L$2&"'!$C$1:$C$500")) -> 0 | M9: =SUMIF(INDIRECT("'"&M$2&"'!$A$1:$A$500"),$K9,INDIRECT("'"&M$2&"'!$C$1:$C$500")) -> 473.53 | N9: =SUMIF(INDIRECT("'"&N$2&"'!$A$1:$A$500"),$K9,INDIRECT("'"&N$2&"'!$C$1:$C$500")) -> 608.23 | O9: =SUMIF(INDIRECT("'"&O$2&"'!$A$1:$A$500"),$K9,INDIRECT("'"&O$2&"'!$C$1:$C$500")) -> 0
B10: Other Current Assets | C10: =IFERROR(AVERAGE(D10:G10),0) -> 0.047883613 | D10: =IFERROR(L10/L$18,0) -> 0.023644136 | E10: =IFERROR(M10/M$18,0) -> 0.057120547 | F10: =IFERROR(N10/N$18,0) -> 0.025981337 | G10: =IFERROR(O10/O$18,0) -> 0.084788433 | K10: Other Current Assets | L10: =SUMIF(INDIRECT("'"&L$2&"'!$A$1:$A$500"),$K11,INDIRECT("'"&L$2&"'!$C$1:$C$500"))-SUM(L6:L9) -> 708 | M10: =SUMIF(INDIRECT("'"&M$2&"'!$A$1:$A$500"),$K11,INDIRECT("'"&M$2&"'!$C$1:$C$500"))-SUM(M6:M9) -> 495.96 | N10: =SUMIF(INDIRECT("'"&N$2&"'!$A$1:$A$500"),$K11,INDIRECT("'"&N$2&"'!$C$1:$C$500"))-SUM(N6:N9) -> 212.75 | O10: =SUMIF(INDIRECT("'"&O$2&"'!$A$1:$A$500"),$K11,INDIRECT("'"&O$2&"'!$C$1:$C$500"))-SUM(O6:O9) -> 1379.49
B11: Total Current Assets | C11: =IFERROR(AVERAGE(D11:G11),0) -> 0.49493785 | D11: =IFERROR(L11/L$18,0) -> 0.20868955 | E11: =IFERROR(M11/M$18,0) -> 0.79458094 | F11: =IFERROR(N11/N$18,0) -> 0.76125502 | G11: =IFERROR(O11/O$18,0) -> 0.21522589 | K11: Total Current Assets | L11: =SUM(L6:L10) -> 6249 | M11: =SUM(M6:M10) -> 6899.1 | N11: =SUM(N6:N10) -> 6233.59 | O11: =SUM(O6:O10) -> 3501.68
K12: Check Current Assets | L12: =ROUND(SUMIF(INDIRECT("'"&L$2&"'!$A$1:$A$500"),$K$11,INDIRECT("'"&L$2&"'!$C$1:$C$500"))-L11,2) -> 0 | M12: =ROUND(SUMIF(INDIRECT("'"&M$2&"'!$A$1:$A$500"),$K$11,INDIRECT("'"&M$2&"'!$C$1:$C$500"))-M11,2) -> 0 | N12: =ROUND(SUMIF(INDIRECT("'"&N$2&"'!$A$1:$A$500"),$K$11,INDIRECT("'"&N$2&"'!$C$1:$C$500"))-N11,2) -> 0 | O12: =ROUND(SUMIF(INDIRECT("'"&O$2&"'!$A$1:$A$500"),$K$11,INDIRECT("'"&O$2&"'!$C$1:$C$500"))-O11,2) -> 0
B13: Investments - Long-Term | C13: =IFERROR(AVERAGE(D13:G13),0) -> 0.004142382 | D13: =IFERROR(L13/L$18,0) -> 0.0036067326 | E13: =IFERROR(M13/M$18,0) -> 0.0054303447 | F13: =IFERROR(N13/N$18,0) -> 0.0075324507 | G13: =IFERROR(O13/O$18,0) -> 0 | K13: Investments - Long-Term | L13: =SUMIF(INDIRECT("'"&L$2&"'!$A$1:$A$500"),$K13,INDIRECT("'"&L$2&"'!$C$1:$C$500")) -> 108 | M13: =SUMIF(INDIRECT("'"&M$2&"'!$A$1:$A$500"),$K13,INDIRECT("'"&M$2&"'!$C$1:$C$500")) -> 47.15 | N13: =SUMIF(INDIRECT("'"&N$2&"'!$A$1:$A$500"),$K13,INDIRECT("'"&N$2&"'!$C$1:$C$500")) -> 61.68 | O13: =SUMIF(INDIRECT("'"&O$2&"'!$A$1:$A$500"),$K13,INDIRECT("'"&O$2&"'!$C$1:$C$500")) -> 0
B14: Property, Plant & Equipment - Net - Total | C14: =IFERROR(AVERAGE(D14:G14),0) -> 0.070967518 | D14: =IFERROR(L14/L$18,0) -> 0.027484638 | E14: =IFERROR(M14/M$18,0) -> 0.0055570336 | F14: =IFERROR(N14/N$18,0) -> 0.21858029 | G14: =IFERROR(O14/O$18,0) -> 0.032248111 | K14: Property, Plant & Equipment - Net - Total | L14: =SUMIF(INDIRECT("'"&L$2&"'!$A$1:$A$500"),$K14,INDIRECT("'"&L$2&"'!$C$1:$C$500")) -> 823 | M14: =SUMIF(INDIRECT("'"&M$2&"'!$A$1:$A$500"),$K14,INDIRECT("'"&M$2&"'!$C$1:$C$500")) -> 48.25 | N14: =SUMIF(INDIRECT("'"&N$2&"'!$A$1:$A$500"),$K14,INDIRECT("'"&N$2&"'!$C$1:$C$500")) -> 1789.86 | O14: =SUMIF(INDIRECT("'"&O$2&"'!$A$1:$A$500"),$K14,INDIRECT("'"&O$2&"'!$C$1:$C$500")) -> 524.67
B15: Intangible Assets - Total - Net | C15: =IFERROR(AVERAGE(D15:G15),0) -> 0.37396698 | D15: =IFERROR(L15/L$18,0) -> 0.72061181 | E15: =IFERROR(M15/M$18,0) -> 0.031338214 | F15: =IFERROR(N15/N$18,0) -> 0.0076570146 | G15: =IFERROR(O15/O$18,0) -> 0.73626089 | K15: Intangible Assets - Total - Net | L15: =SUMIF(INDIRECT("'"&L$2&"'!$A$1:$A$500"),$K15,INDIRECT("'"&L$2&"'!$C$1:$C$500")) -> 21578 | M15: =SUMIF(INDIRECT("'"&M$2&"'!$A$1:$A$500"),$K15,INDIRECT("'"&M$2&"'!$C$1:$C$500")) -> 272.1 | N15: =SUMIF(INDIRECT("'"&N$2&"'!$A$1:$A$500"),$K15,INDIRECT("'"&N$2&"'!$C$1:$C$500")) -> 62.7 | O15: =SUMIF(INDIRECT("'"&O$2&"'!$A$1:$A$500"),$K15,INDIRECT("'"&O$2&"'!$C$1:$C$500")) -> 11978.81
B16: Other Non-Current Assets | C16: =IFERROR(AVERAGE(D16:G16),0) -> 0.055985269 | D16: =IFERROR(L16/L$18,0) -> 0.039607267 | E16: =IFERROR(M16/M$18,0) -> 0.16309347 | F16: =IFERROR(N16/N$18,0) -> 0.0049752277 | G16: =IFERROR(O16/O$18,0) -> 0.016265115 | K16: Other Non-Current Assets | L16: =SUMIF(INDIRECT("'"&L$2&"'!$A$1:$A$500"),$K17,INDIRECT("'"&L$2&"'!$C$1:$C$500"))-SUM(L12:L15) -> 1186 | M16: =SUMIF(INDIRECT("'"&M$2&"'!$A$1:$A$500"),$K17,INDIRECT("'"&M$2&"'!$C$1:$C$500"))-SUM(M12:M15) -> 1416.09 | N16: =SUMIF(INDIRECT("'"&N$2&"'!$A$1:$A$500"),$K17,INDIRECT("'"&N$2&"'!$C$1:$C$500"))-SUM(N12:N15) -> 40.74 | O16: =SUMIF(INDIRECT("'"&O$2&"'!$A$1:$A$500"),$K17,INDIRECT("'"&O$2&"'!$C$1:$C$500"))-SUM(O12:O15) -> 264.63
B17: Total Non-Current Assets | C17: =IFERROR(AVERAGE(D17:G17),0) -> 0.50506215 | D17: =IFERROR(L17/L$18,0) -> 0.79131045 | E17: =IFERROR(M17/M$18,0) -> 0.20541906 | F17: =IFERROR(N17/N$18,0) -> 0.23874498 | G17: =IFERROR(O17/O$18,0) -> 0.78477411 | K17: Total Non-Current Assets | L17: =SUM(L13:L16) -> 23695 | M17: =SUM(M13:M16) -> 1783.59 | N17: =SUM(N13:N16) -> 1954.98 | O17: =SUM(O13:O16) -> 12768.11
B18: Total Assets | C18: =IFERROR(AVERAGE(D18:G18),0) -> 1 | D18: =IFERROR(L18/L$18,0) -> 1 | E18: =IFERROR(M18/M$18,0) -> 1 | F18: =IFERROR(N18/N$18,0) -> 1 | G18: =IFERROR(O18/O$18,0) -> 1 | K18: Total Assets | L18: =L17+L11 -> 29944 | M18: =M17+M11 -> 8682.69 | N18: =N17+N11 -> 8188.57 | O18: =O17+O11 -> 16269.79
K19: Check Total Assets | L19: =ROUND(SUMIF(INDIRECT("'"&L$2&"'!$A$1:$A$500"),$K$18,INDIRECT("'"&L$2&"'!$C$1:$C$500"))-L18,2) -> 0 | M19: =ROUND(SUMIF(INDIRECT("'"&M$2&"'!$A$1:$A$500"),$K$18,INDIRECT("'"&M$2&"'!$C$1:$C$500"))-M18,2) -> 0.01 | N19: =ROUND(SUMIF(INDIRECT("'"&N$2&"'!$A$1:$A$500"),$K$18,INDIRECT("'"&N$2&"'!$C$1:$C$500"))-N18,2) -> 0 | O19: =ROUND(SUMIF(INDIRECT("'"&O$2&"'!$A$1:$A$500"),$K$18,INDIRECT("'"&O$2&"'!$C$1:$C$500"))-O18,2) -> -0.01
B20: Trade Accounts & Trade Notes Payable - Short-Term | C20: =IFERROR(AVERAGE(D20:G20),0) -> 0.040048569 | D20: =IFERROR(L20/L$18,0) -> 0.026048624 | E20: =IFERROR(M20/M$18,0) -> 0.063836207 | F20: =IFERROR(N20/N$18,0) -> 0.058501057 | G20: =IFERROR(O20/O$18,0) -> 0.011808388 | K20: Trade Accounts & Trade Notes Payable - Short-Term | L20: =SUMIF(INDIRECT("'"&L$2&"'!$A$1:$A$500"),$K20,INDIRECT("'"&L$2&"'!$C$1:$C$500")) -> 780 | M20: =SUMIF(INDIRECT("'"&M$2&"'!$A$1:$A$500"),$K20,INDIRECT("'"&M$2&"'!$C$1:$C$500")) -> 554.27 | N20: =SUMIF(INDIRECT("'"&N$2&"'!$A$1:$A$500"),$K20,INDIRECT("'"&N$2&"'!$C$1:$C$500")) -> 479.04 | O20: =SUMIF(INDIRECT("'"&O$2&"'!$A$1:$A$500"),$K20,INDIRECT("'"&O$2&"'!$C$1:$C$500")) -> 192.12
